<?xml version="1.0" ?>
<robot name="xycar" xmlns:xacro="http://www.ros.org/wiki/xacro">
  <!--
 1. Create model with URDF: http://wiki.ros.org/urdf/Tutorials/Create%20your%20own%20urdf%20file
 2. Add controllable joints: http://wiki.ros.org/urdf/Tutorials/Building%20a%20Movable%20Robot%20Model%20with%20URDF
 3. Physical properties: http://wiki.ros.org/urdf/Tutorials/Adding%20Physical%20and%20Collision%20Properties%20to%20a%20URDF%20Model or http://gazebosim.org/tutorials/?tut=ros_urdf
 4. Use Macros: http://wiki.ros.org/urdf/Tutorials/Using%20Xacro%20to%20Clean%20Up%20a%20URDF%20File
 5. Link to Gazebo: http://wiki.ros.org/urdf/Tutorials/Using%20a%20URDF%20in%20Gazebo
-->
  <!-- Inspired from https://github.com/DJTobias/Cherry-Autonomous-Racecar/blob/master/urdf/car.urdf
     and https://github.com/mit-racecar/racecar-simulator/blob/master/racecar_description/urdf/racecar.xacro
-->
  <!-- X axis direction is forward, Y axis direction is left -->
  <!-- X axis direction is forward, Y axis direction is left -->
  <!-- Transmissions are motors attached to a certain joint. We thus need to instantiate transmissions at the corresponding joints -->
  <!-- A transmission consists of an actuator (commanded output) and a sensor (for feedback) 
	     These interfaces are used as abstraction layers between controllers and the actual hardware.
	-->
  <!-- Possible hardware interfaces:
		EffortJointInterface		-  	similar to torque/acceleration control
		VelocityJointInterface		-	references given as velocity (linear/angular)
		PositionJointInterface		-	references given as position (linear/angular)
	-->
  <!-- Notice that the two transmission types above are identical - only the naming convention is different -->
  <link name="base_link"/>

  <!-- because origin is in the center, we want the IMU to stand on the baseplate -->
  <link name="baseplate">
    <visual>
      <material name="acrylic"/>
      <origin rpy="0 0 0" xyz="0 0 0.03375"/>
      <!-- origin (0,0,0) is in the center of the box, so place the origin of this in the bottom of baseplate -->
      <geometry>
        <box size="0.5 0.2 0.0675"/>
        <!-- 50x20x6.75 cm, X-axis is front of vehicle -->
      </geometry>
    </visual>
    <collision>
      <origin rpy="0 0 0" xyz="0 0 0.03375"/>
      <!-- origin (0,0,0) is in the center of the box, so place the origin of this in the bottom of baseplate -->
      <geometry>
        <box size="0.5 0.2 0.0675"/>
        <!-- 50x20x6.75 cm, X-axis is front of vehicle -->
      </geometry>
    </collision>
    <inertial>
      <origin rpy="0 0 0" xyz="0 0 0.03375"/>
      <mass value="2.0"/>
      <inertia ixx="0.00371302083333" ixy="0" ixz="0" iyy="0.0212130208333" iyz="0" izz="0.0241666666667"/>
    </inertial>
  </link>
  <joint name="base_link_to_baseplate" type="fixed">
    <parent link="base_link"/>
    <child link="baseplate"/>
    <origin rpy="0 0 0" xyz="0 0 0"/>
    <!-- offset from parent to child, so with direction based in parent frame -->
  </joint>
  <link name="front_mount">
    <visual>
      <material name="grey"/>
      <origin rpy="0 0.0 0" xyz="-0.105 0 0"/>
      <!-- origin (0,0,0) is in the center of the box -->
      <geometry>
        <box size="0.50 0.12 0.01"/>
      </geometry>
    </visual>
    <collision>
      <origin rpy="0 0.0 0" xyz="-0.105 0 0"/>
      <!-- origin (0,0,0) is in the center of the box -->
      <geometry>
        <box size="0.50 0.12 0.01"/>
      </geometry>
    </collision>
    <inertial>
      <origin rpy="0 0.0 0" xyz="-0.105 0 0"/>
      <mass value="0.5"/>
      <inertia ixx="0.000604166666667" ixy="0" ixz="0" iyy="0.00240416666667" iyz="0" izz="0.003"/>
    </inertial>
  </link>
  <joint name="baseplate_to_front_mount" type="fixed">
    <parent link="baseplate"/>
    <child link="front_mount"/>
    <origin rpy="0 0 0" xyz="0.105 0 -0.059"/>
    <!-- offset from parent to child, so with direction based in parent frame -->
  </joint>

  <link name="front_shaft">
    <visual>
      <material name="black"/>
      <origin rpy="1.570796327 0 0" xyz="0 0 0"/>
      <!-- origin (0,0,0) is in the center of the cylinder -->
      <geometry>
        <cylinder length="0.285" radius="0.018"/>
        <!-- confirm length between wheels -->
      </geometry>
    </visual>
    <collision>
      <origin rpy="1.570796327 0 0" xyz="0 0 0"/>
      <!-- origin (0,0,0) is in the center of the cylinder -->
      <geometry>
        <cylinder length="0.285" radius="0.018"/>
        <!-- confirm length between wheels -->
      </geometry>
    </collision>
    <inertial>
      <origin rpy="1.570796327 0 0" xyz="0 0 0"/>
      <mass value="0.1"/>
      <inertia ixx="0.000684975" ixy="0" ixz="0" iyy="0.000684975" iyz="0" izz="1.62e-05"/>
    </inertial>
  </link>
  <joint name="front_mount_to_front_shaft" type="fixed">
    <parent link="front_mount"/>
    <child link="front_shaft"/>
    <origin rpy="0 0 0" xyz="0.105 0 -0.059"/>
    <!-- offset from parent to child, so with direction based in parent frame -->
  </joint>
  <!--<xacro:dampener_joint parent="front_mount" child="front_shaft" offset="${front_to_rear_wheel_center/4} 0 -${baseplate_to_wheel_center/2}"/> I can not get the dampener joint to work properly. The car seems to be bouncing around, like the spring is too hard and dampening is too little. I already tried adjusting several parameters. -->
  <link name="rear_shaft">
    <visual>
      <material name="black"/>
      <origin rpy="1.570796327 0 0" xyz="0 0 0"/>
      <!-- origin (0,0,0) is in the center of the cylinder -->
      <geometry>
        <cylinder length="0.285" radius="0.018"/>
        <!-- confirm length between wheels -->
      </geometry>
    </visual>
    <collision>
      <origin rpy="1.570796327 0 0" xyz="0 0 0"/>
      <!-- origin (0,0,0) is in the center of the cylinder -->
      <geometry>
        <cylinder length="0.285" radius="0.018"/>
        <!-- confirm length between wheels -->
      </geometry>
    </collision>
    <inertial>
      <origin rpy="1.570796327 0 0" xyz="0 0 0"/>
      <mass value="0.1"/>
      <inertia ixx="0.000684975" ixy="0" ixz="0" iyy="0.000684975" iyz="0" izz="1.62e-05"/>
    </inertial>
  </link>
  <joint name="rear_mount_to_rear_shaft" type="fixed">
    <parent link="front_mount"/>
    <child link="rear_shaft"/>
    <origin rpy="0 0 0" xyz="-0.305 0 -0.059"/>
    <!-- offset from parent to child, so with direction based in parent frame -->
  </joint>
  <!-- <xacro:dampener_joint parent="rear_mount" child="rear_shaft" offset="-${front_to_rear_wheel_center/4} 0 -${baseplate_to_wheel_center/2}"/> I can not get the dampener joint to work properly. The car seems to be bouncing around, like the spring is too hard and dampening is too little. I already tried adjusting several parameters. -->
  <link name="front_right_hinge">
    <visual>
      <material name="white"/>
      <origin rpy="0 0 0" xyz="0 0 0"/>
      <geometry>
        <sphere radius="0.015"/>
      </geometry>
    </visual>
    <!--<collision>
			<xacro:hinge_geometry/>
		</collision>-->
    <inertial>
      <origin rpy="0 0 0" xyz="0 0 0"/>
      <mass value="0.05"/>
      <inertia ixx="1e-6" ixy="0" ixz="0" iyy="1e-6" iyz="0" izz="1e-6"/>
      <!-- small inertia -->
    </inertial>
  </link>
  <joint name="front_right_hinge_joint" type="revolute">
    <!-- revolute is a joint with a range limited motion around its' axis -->
    <parent link="front_shaft"/>
    <child link="front_right_hinge"/>
    <origin rpy="0 0 0" xyz="0 -0.1425 0"/>
    <!-- offset from parent to child, so with direction based in parent frame -->
    <axis xyz="0 0 1"/>
    <limit effort="10" lower="-0.349065850399" upper="0.349065850399" velocity="100"/>
    <!-- effeort is similar to torque/acceleration -->
    <!-- friction - The physical static friction. For prismatic joints, the units are Newtons. For revolving joints, the units are Newton meters. -->
    <!-- damping - The physical damping value. For prismatic joints, the units are Newton seconds per meter. For revolving joints, Newton meter secons per radian. -->
    <!--<dynamics friction="0.0" damping="0.0"/>-->
  </joint>
  <transmission name="front_right_hinge_transmission" type="SimpleTransmission">
    <type>transmission_interface/SimpleTransmission</type>
    <joint name="front_right_hinge_joint">
      <hardwareInterface>hardware_interface/EffortJointInterface</hardwareInterface>
    </joint>
    <actuator name="front_right_hinge_motor">
      <!-- The motor is torque controlled -->
      <hardwareInterface>hardware_interface/EffortJointInterface</hardwareInterface>
      <mechanicalReduction>1</mechanicalReduction>
    </actuator>
  </transmission>
  <link name="front_left_hinge">
    <visual>
      <material name="white"/>
      <origin rpy="0 0 0" xyz="0 0 0"/>
      <geometry>
        <sphere radius="0.015"/>
      </geometry>
    </visual>
    <!--<collision>
			<xacro:hinge_geometry/>
		</collision>-->
    <inertial>
      <origin rpy="0 0 0" xyz="0 0 0"/>
      <mass value="0.05"/>
      <inertia ixx="1e-6" ixy="0" ixz="0" iyy="1e-6" iyz="0" izz="1e-6"/>
      <!-- small inertia -->
    </inertial>
  </link>
  <joint name="front_left_hinge_joint" type="revolute">
    <!-- revolute is a joint with a range limited motion around its' axis -->
    <parent link="front_shaft"/>
    <child link="front_left_hinge"/>
    <origin rpy="0 0 0" xyz="0 0.1425 0"/>
    <!-- offset from parent to child, so with direction based in parent frame -->
    <axis xyz="0 0 1"/>
    <limit effort="10" lower="-0.349065850399" upper="0.349065850399" velocity="100"/>
    <!-- effeort is similar to torque/acceleration -->
    <!-- friction - The physical static friction. For prismatic joints, the units are Newtons. For revolving joints, the units are Newton meters. -->
    <!-- damping - The physical damping value. For prismatic joints, the units are Newton seconds per meter. For revolving joints, Newton meter secons per radian. -->
    <!--<dynamics friction="0.0" damping="0.0"/>-->
  </joint>
  <transmission name="front_left_hinge_transmission" type="SimpleTransmission">
    <type>transmission_interface/SimpleTransmission</type>
    <joint name="front_left_hinge_joint">
      <hardwareInterface>hardware_interface/EffortJointInterface</hardwareInterface>
    </joint>
    <actuator name="front_left_hinge_motor">
      <!-- The motor is torque controlled -->
      <hardwareInterface>hardware_interface/EffortJointInterface</hardwareInterface>
      <mechanicalReduction>1</mechanicalReduction>
    </actuator>
  </transmission>
  <link name="front_right_wheel">
    <visual>
      <material name="black"/>
      <origin rpy="1.570796327 0 0" xyz="0 0 0"/>
      <!-- origin (0,0,0) is in the center of the cylinder -->
      <geometry>
        <cylinder length="0.064" radius="0.0775"/>
      </geometry>
    </visual>
    <collision>
      <origin rpy="1.570796327 0 0" xyz="0 0 0"/>
      <!-- origin (0,0,0) is in the center of the cylinder -->
      <geometry>
        <cylinder length="0.064" radius="0.0775"/>
      </geometry>
      <!--<contact_coefficients mu="0" kp="1000.0" kd="1.0"/>-->
      <!-- mu=The friction coefficient, kp=Stiffness coefficient, kd=Dampening coefficient -->
    </collision>
    <inertial>
      <origin rpy="1.570796327 0 0" xyz="0 0 0"/>
      <mass value="0.15"/>
      <inertia ixx="0.000276434375" ixy="0" ixz="0" iyy="0.000276434375" iyz="0" izz="0.00045046875"/>
    </inertial>
  </link>
  <joint name="front_right_wheel_joint" type="continuous">
    <!-- continuous is a joint of continous motion around its' axis -->
    <parent link="front_right_hinge"/>
    <child link="front_right_wheel"/>
    <origin rpy="0 0 0" xyz="0 0 0"/>
    <!-- offset from parent to child, so with direction based in parent frame -->
    <axis xyz="0 1 0"/>
    <!-- friction - The physical static friction. For prismatic joints, the units are Newtons. For revolving joints, the units are Newton meters. -->
    <!-- damping - The physical damping value. For prismatic joints, the units are Newton seconds per meter. For revolving joints, Newton meter secons per radian. -->
    <!--<dynamics friction="0.0" damping="0.0"/>-->
    <limit effort="10" velocity="100"/>
  </joint>
  <transmission name="front_right_wheel_transmission" type="SimpleTransmission">
    <type>transmission_interface/SimpleTransmission</type>
    <joint name="front_right_wheel_joint">
      <hardwareInterface>hardware_interface/EffortJointInterface</hardwareInterface>
    </joint>
    <actuator name="front_right_wheel_motor">
      <!-- The motor is torque controlled -->
      <hardwareInterface>hardware_interface/EffortJointInterface</hardwareInterface>
      <mechanicalReduction>1</mechanicalReduction>
    </actuator>
  </transmission>
  <link name="front_left_wheel">
    <visual>
      <material name="black"/>
      <origin rpy="1.570796327 0 0" xyz="0 0 0"/>
      <!-- origin (0,0,0) is in the center of the cylinder -->
      <geometry>
        <cylinder length="0.064" radius="0.0775"/>
      </geometry>
    </visual>
    <collision>
      <origin rpy="1.570796327 0 0" xyz="0 0 0"/>
      <!-- origin (0,0,0) is in the center of the cylinder -->
      <geometry>
        <cylinder length="0.064" radius="0.0775"/>
      </geometry>
      <!--<contact_coefficients mu="0" kp="1000.0" kd="1.0"/>-->
      <!-- mu=The friction coefficient, kp=Stiffness coefficient, kd=Dampening coefficient -->
    </collision>
    <inertial>
      <origin rpy="1.570796327 0 0" xyz="0 0 0"/>
      <mass value="0.15"/>
      <inertia ixx="0.000276434375" ixy="0" ixz="0" iyy="0.000276434375" iyz="0" izz="0.00045046875"/>
    </inertial>
  </link>
  <joint name="front_left_wheel_joint" type="continuous">
    <!-- continuous is a joint of continous motion around its' axis -->
    <parent link="front_left_hinge"/>
    <child link="front_left_wheel"/>
    <origin rpy="0 0 0" xyz="0 0 0"/>
    <!-- offset from parent to child, so with direction based in parent frame -->
    <axis xyz="0 1 0"/>
    <!-- friction - The physical static friction. For prismatic joints, the units are Newtons. For revolving joints, the units are Newton meters. -->
    <!-- damping - The physical damping value. For prismatic joints, the units are Newton seconds per meter. For revolving joints, Newton meter secons per radian. -->
    <!--<dynamics friction="0.0" damping="0.0"/>-->
    <limit effort="10" velocity="100"/>
  </joint>
  <transmission name="front_left_wheel_transmission" type="SimpleTransmission">
    <type>transmission_interface/SimpleTransmission</type>
    <joint name="front_left_wheel_joint">
      <hardwareInterface>hardware_interface/EffortJointInterface</hardwareInterface>
    </joint>
    <actuator name="front_left_wheel_motor">
      <!-- The motor is torque controlled -->
      <hardwareInterface>hardware_interface/EffortJointInterface</hardwareInterface>
      <mechanicalReduction>1</mechanicalReduction>
    </actuator>
  </transmission>
  <link name="rear_right_wheel">
    <visual>
      <material name="black"/>
      <origin rpy="1.570796327 0 0" xyz="0 0 0"/>
      <!-- origin (0,0,0) is in the center of the cylinder -->
      <geometry>
        <cylinder length="0.064" radius="0.0775"/>
      </geometry>
    </visual>
    <collision>
      <origin rpy="1.570796327 0 0" xyz="0 0 0"/>
      <!-- origin (0,0,0) is in the center of the cylinder -->
      <geometry>
        <cylinder length="0.064" radius="0.0775"/>
      </geometry>
      <!--<contact_coefficients mu="0" kp="1000.0" kd="1.0"/>-->
      <!-- mu=The friction coefficient, kp=Stiffness coefficient, kd=Dampening coefficient -->
    </collision>
    <inertial>
      <origin rpy="1.570796327 0 0" xyz="0 0 0"/>
      <mass value="0.15"/>
      <inertia ixx="0.000276434375" ixy="0" ixz="0" iyy="0.000276434375" iyz="0" izz="0.00045046875"/>
    </inertial>
  </link>
  <joint name="rear_right_wheel_joint" type="continuous">
    <!-- continuous is a joint of continous motion around its' axis -->
    <parent link="rear_shaft"/>
    <child link="rear_right_wheel"/>
    <origin rpy="0 0 0" xyz="0 -0.1425 0"/>
    <!-- offset from parent to child, so with direction based in parent frame -->
    <axis xyz="0 1 0"/>
    <!-- friction - The physical static friction. For prismatic joints, the units are Newtons. For revolving joints, the units are Newton meters. -->
    <!-- damping - The physical damping value. For prismatic joints, the units are Newton seconds per meter. For revolving joints, Newton meter secons per radian. -->
    <!--<dynamics friction="0.0" damping="0.0"/>-->
    <limit effort="10" velocity="100"/>
  </joint>
  <transmission name="rear_right_wheel_transmission" type="SimpleTransmission">
    <type>transmission_interface/SimpleTransmission</type>
    <joint name="rear_right_wheel_joint">
      <hardwareInterface>hardware_interface/EffortJointInterface</hardwareInterface>
    </joint>
    <actuator name="rear_right_wheel_motor">
      <!-- The motor is torque controlled -->
      <hardwareInterface>hardware_interface/EffortJointInterface</hardwareInterface>
      <mechanicalReduction>1</mechanicalReduction>
    </actuator>
  </transmission>
  <link name="rear_left_wheel">
    <visual>
      <material name="black"/>
      <origin rpy="1.570796327 0 0" xyz="0 0 0"/>
      <!-- origin (0,0,0) is in the center of the cylinder -->
      <geometry>
        <cylinder length="0.064" radius="0.0775"/>
      </geometry>
    </visual>
    <collision>
      <origin rpy="1.570796327 0 0" xyz="0 0 0"/>
      <!-- origin (0,0,0) is in the center of the cylinder -->
      <geometry>
        <cylinder length="0.064" radius="0.0775"/>
      </geometry>
      <!--<contact_coefficients mu="0" kp="1000.0" kd="1.0"/>-->
      <!-- mu=The friction coefficient, kp=Stiffness coefficient, kd=Dampening coefficient -->
    </collision>
    <inertial>
      <origin rpy="1.570796327 0 0" xyz="0 0 0"/>
      <mass value="0.15"/>
      <inertia ixx="0.000276434375" ixy="0" ixz="0" iyy="0.000276434375" iyz="0" izz="0.00045046875"/>
    </inertial>
  </link>
  <joint name="rear_left_wheel_joint" type="continuous">
    <!-- continuous is a joint of continous motion around its' axis -->
    <parent link="rear_shaft"/>
    <child link="rear_left_wheel"/>
    <origin rpy="0 0 0" xyz="0 0.1425 0"/>
    <!-- offset from parent to child, so with direction based in parent frame -->
    <axis xyz="0 1 0"/>
    <!-- friction - The physical static friction. For prismatic joints, the units are Newtons. For revolving joints, the units are Newton meters. -->
    <!-- damping - The physical damping value. For prismatic joints, the units are Newton seconds per meter. For revolving joints, Newton meter secons per radian. -->
    <!--<dynamics friction="0.0" damping="0.0"/>-->
    <limit effort="10" velocity="100"/>
  </joint>
  <transmission name="rear_left_wheel_transmission" type="SimpleTransmission">
    <type>transmission_interface/SimpleTransmission</type>
    <joint name="rear_left_wheel_joint">
      <hardwareInterface>hardware_interface/EffortJointInterface</hardwareInterface>
    </joint>
    <actuator name="rear_left_wheel_motor">
      <!-- The motor is torque controlled -->
      <hardwareInterface>hardware_interface/EffortJointInterface</hardwareInterface>
      <mechanicalReduction>1</mechanicalReduction>
    </actuator>
  </transmission>
  <!-- Sensors -->
  <link name="left_camera_mount">
    <visual>
      <material name="blue"/>
      <origin rpy="0 0 0" xyz="0 0 0.025"/>
      <!-- origin (0,0,0) is in the center of the box -->
      <geometry>
        <cylinder length="0.05" radius="0.005"/>
        <!-- confirm length between wheels -->
      </geometry>
    </visual>
    <collision>
      <origin rpy="0 0 0" xyz="0 0 0.025"/>
      <!-- origin (0,0,0) is in the center of the box -->
      <geometry>
        <cylinder length="0.05" radius="0.005"/>
        <!-- confirm length between wheels -->
      </geometry>
    </collision>
    <inertial>
      <origin rpy="0 0 0" xyz="0 0 0"/>
      <!-- origin (0,0,0) is in the center of the box -->
      <mass value="0.005"/>
      <!-- 5 grams -->
      <inertia ixx="1e-6" ixy="0" ixz="0" iyy="1e-6" iyz="0" izz="1e-6"/>
      <!-- small inertia -->
    </inertial>
  </link>
  <joint name="baseplate_to_left_camera_mount" type="fixed">
    <parent link="baseplate"/>
    <child link="left_camera_mount"/>
    <origin rpy="0 0 0" xyz="0.23 0.07 0.0675"/>
    <!-- offset from parent to child, so with direction based in parent frame -->
  </joint>
  <link name="left_camera">
    <visual>
      <material name="black"/>
      <origin rpy="0 0 0" xyz="0 0 0"/>
      <!-- origin (0,0,0) is in the center of the box -->
      <geometry>
        <box size="0.024 0.060 0.029"/>
      </geometry>
    </visual>
    <collision>
      <origin rpy="0 0 0" xyz="0 0 0"/>
      <!-- origin (0,0,0) is in the center of the box -->
      <geometry>
        <box size="0.024 0.060 0.029"/>
      </geometry>
    </collision>
    <inertial>
      <origin rpy="0 0 0" xyz="0 0 0"/>
      <mass value="0.162"/>
      <inertia ixx="0.0001306395" ixy="0" ixz="0" iyy="1.91295e-05" iyz="0" izz="0.000127062"/>
    </inertial>
  </link>
  <joint name="left_camera_mount_to_left_camera" type="fixed">
    <parent link="left_camera_mount"/>
    <child link="left_camera"/>
    <origin rpy="0 0 0" xyz="0 0 0.0645"/>
    <!-- offset from parent to child, so with direction based in parent frame -->
  </joint>
  <link name="right_camera_mount">
    <visual>
      <material name="blue"/>
      <origin rpy="0 0 0" xyz="0 0 0.025"/>
      <!-- origin (0,0,0) is in the center of the box -->
      <geometry>
        <cylinder length="0.05" radius="0.005"/>
        <!-- confirm length between wheels -->
      </geometry>
    </visual>
    <collision>
      <origin rpy="0 0 0" xyz="0 0 0.025"/>
      <!-- origin (0,0,0) is in the center of the box -->
      <geometry>
        <cylinder length="0.05" radius="0.005"/>
        <!-- confirm length between wheels -->
      </geometry>
    </collision>
    <inertial>
      <origin rpy="0 0 0" xyz="0 0 0"/>
      <!-- origin (0,0,0) is in the center of the box -->
      <mass value="0.005"/>
      <!-- 5 grams -->
      <inertia ixx="1e-6" ixy="0" ixz="0" iyy="1e-6" iyz="0" izz="1e-6"/>
      <!-- small inertia -->
    </inertial>
  </link>
  <joint name="baseplate_to_right_camera_mount" type="fixed">
    <parent link="baseplate"/>
    <child link="right_camera_mount"/>
    <origin rpy="0 0 0" xyz="0.23 -0.07 0.0675"/>
    <!-- offset from parent to child, so with direction based in parent frame -->
  </joint>
  <link name="right_camera">
    <visual>
      <material name="blue"/>
      <origin rpy="0 0 0" xyz="0 0 0"/>
      <!-- origin (0,0,0) is in the center of the box -->
      <geometry>
        <box size="0.024 0.094 0.029"/>
      </geometry>
    </visual>
    <collision>
      <origin rpy="0 0 0" xyz="0 0 0"/>
      <!-- origin (0,0,0) is in the center of the box -->
      <geometry>
        <box size="0.024 0.094 0.029"/>
      </geometry>
    </collision>
    <inertial>
      <origin rpy="0 0 0" xyz="0 0 0"/>
      <mass value="0.162"/>
      <inertia ixx="0.0001306395" ixy="0" ixz="0" iyy="1.91295e-05" iyz="0" izz="0.000127062"/>
    </inertial>
  </link>
  <joint name="right_camera_mount_to_right_camera" type="fixed">
    <parent link="right_camera_mount"/>
    <child link="right_camera"/>
    <origin rpy="0 0 0" xyz="0 0 0.0645"/>
    <!-- offset from parent to child, so with direction based in parent frame -->
  </joint>
  <!-- include the Gazebo description of the JetsonCar -->
  <!-- see the guide: http://wiki.ros.org/urdf/Tutorials/Using%20a%20URDF%20in%20Gazebo -->
  <!-- inspired from https://github.com/mit-racecar/racecar-simulator/blob/master/racecar_description/urdf/racecar.gazebo and https://github.com/husky/husky_simulator/blob/indigo-devel/husky_gazebo/urdf/husky.gazebo.xacro -->
  <!-- Visual and physical properties -->
  <!-- See http://gazebosim.org/tutorials?tut=ros_urdf&cat=connect_ros -->
 <!-- We need to link Gazebo and ROS and let Gazebo load all the previously defined ROS parameters. Therefore this Gazebo file should be included in the end of the main xacro file! -->
  <!-- Link Gazebo and ROS -->
  <gazebo>
    <plugin filename="libgazebo_ros_control.so" name="gazebo_ros_control">
      <robotNamespace>/xycar</robotNamespace>
      <robotSimType>gazebo_ros_control/DefaultRobotHWSim</robotSimType>
    </plugin>
  </gazebo> 
  <!-- Plugins, eg. sensors -->
  <!-- hokuyo LiDAR can be found here: https://github.com/mit-racecar/racecar-simulator/blob/master/racecar_description/urdf/racecar.gazebo#L59 -->
  <!-- camera sensor might be found here: https://github.com/JoshMarino/gazebo_and_ros_control or here: http://gazebosim.org/tutorials?tut=ros_gzplugins -->
  <material name="black">
    <color rgba="0.0 0.0 0.0 1.0"/>
  </material>
  <material name="blue">
    <color rgba="0.0 0.0 0.8 1.0"/>
  </material>
  <material name="green">
    <color rgba="0.0 0.8 0.0 1.0"/>
  </material>
  <material name="grey">
    <color rgba="0.2 0.2 0.2 1.0"/>
  </material>
  <material name="orange">
    <color rgba="1.0 0.423529411765 0.0392156862745 1.0"/>
  </material>
  <material name="brown">
    <color rgba="0.870588235294 0.811764705882 0.764705882353 1.0"/>
  </material>
  <material name="red">
    <color rgba="0.8 0.0 0.0 1.0"/>
  </material>
  <material name="white">
    <color rgba="1.0 1.0 1.0 1.0"/>
  </material>
  <material name="acrylic">
    <color rgba="1.0 1.0 1.0 0.4"/>
  </material>
</robot>

